Workbook

Sheet Accounting in Action 1
L2: = | M2: Liabillies | N2: + | O2: Equity | Y2: Softbyte Inc.
C3: Trans Action | E3: Cash | F3: + | G3: Accounts Receivable | H3: + | I3: Supplies | J3: + | K3: Equipment | L3: = | M3: Accounts Payable | N3: + | O3: Share Capital | P3: + | Q3: Revenue | R3: - | S3: Expense | T3: - | U3: Drawings | Y3: Income Statement
C4: 1 | E4: 15000 | O4: 15000 | V4: Shere | Y4: For the Month Ended September 30,2024
C5: 2 | E5: -7000 | K5: 7000
C6: 3 | I6: 1600 | M6: 1600 | Z6: Revenues | AE6: =Q16 -> 4700
C7: 4 | E7: 1200 | Q7: 1200 | V7: Serive Revenue | Z7: Serive Revenue
C8: 5 | M8: 250 | S8: 250 | V8: Adver. Expense | Z8: Expense
C9: 6 | E9: 1500 | G9: 2000 | Q9: 3500 | V9: Serive Revenue | Z9: Salaries and Wages expense | AD9: =S11 -> 900
C10: 7 | E10: -1700 | S10: 600 | V10: Rent Expense | Z10: Rent Expense | AD10: =S10 -> 600
S11: 900 | V11: Sal.\Wages Exp | Z11: Advertising. Expense | AD11: =S8 -> 250
S12: 200 | V12: Untilities Expense | Z12: Untilities Expense | AD12: =S12 -> 200
C13: 8 | E13: -250 | M13: -250 | Z13: Total Expense | AE13: =SUM(AD9:AD12) -> 1950
C14: 9 | E14: 600 | G14: -600 | Z14: Net income | AE14: =AE6-AE13 -> 2750
C15: 10 | E15: -1300 | U15: 1300 | V15: Withdrawing
E16: =SUM(E4:E15) -> 8050 | F16: + | G16: =SUM(G4:G15) -> 1400 | H16: + | I16: =SUM(I4:I15) -> 1600 | J16: + | K16: =SUM(K4:K15) -> 7000 | L16: = | M16: =SUM(M4:M15) -> 1600 | N16: + | O16: =SUM(O4:O15) -> 15000 | P16: + | Q16: =SUM(Q4:Q15) -> 4700 | R16: - | S16: =SUM(S4:S15) -> 1950 | T16: - | U16: =SUM(U4:U15) -> 1300
E17: =E16+G16+I16+K16 -> 18050 | L17: = | M17: =M16 -> 1600 | N17: + | O17: =M17+O16+Q16-S16-U16 -> 18050 | Y17: Softbyte Inc.
Y18: Retained Ernings Statement
Y19: For the Month Ended September 30,204
Z21: Retined earinihg, September 1 | AE21: 0
Z22: Add: Net income | AE22: =AE14 -> 2750
AE23: =AE21+AE22 -> 2750
Z24: Less: Drawings | AE24: =U16 -> 1300
Z25: Retined earinihg, September 30 | AE25: =AE23-AE24 -> 1450
Y28: Softbyte Inc.
Y29: Balance Sheet
Y30: For the Month Ended September 30,204
Y31: Assets
Z32: =K3 -> Equipment | AE32: =K16 -> 7000
Z33: =I3 -> Supplies | AE33: =I16 -> 1600
Z34: =G3 -> Accounts Receivable | AE34: =G16 -> 1400
Z35: =E3 -> Cash | AE35: =E16 -> 8050
Z36: Total Assets | AE36: =SUM(AE32:AE35) -> 18050
Z37: Equity and Liabilities
Z38: =O2 -> Equity
Z39: =O3 -> Share Capital | AD39: =O16 -> 15000
Z40: =Z25 -> Retined earinihg, September 30 | AD40: =AE25 -> 1450 | AE40: =AD39+AD40 -> 16450
Z41: =M2 -> Liabillies
Z42: =M3 -> Accounts Payable | AE42: =M16 -> 1600
Z43: Total Equity and Liabilities | AE43: =AE40+AE42 -> 18050
Y46: Softbyte Inc.
...

Sheet f
B3: GENERAL JOURNAL | F3: J2 | H3: Cash | O3: Accounts Payable | V3: PIONEER ADVERTISING
B4: Date | C4: Account Title | D4: Ref… | E4: Debit | F4: Credit | H4: No. 101 | O4: No. 201 | V4: Trial Balance
B5: 2017 Oct. 1 | C5: Cash | D5: 101 | E5: 10000 | H5: Date | I5: Explanation | J5: Ref… | K5: Debit + | L5: Credit - | M5: Balance | O5: Date | P5: Explanation | Q5: Ref… | R5: Debit - | S5: Credit + | T5: Balance | V5: October 31,2017
C6: Owner's Capital | D6: 301 | F6: 10000 | H6: 2017 Oct. 1 | J6: J1 | K6: 10000 | M6: =K6 -> 10000 | O6: 2017 Oct. 4 | Q6: J1 | S6: 2500 | T6: =S6 -> 2500
C7: (Owner's investment of cash in business) | H7: 2 | J7: J1 | K7: 1200 | M7: =M6+K7-L7 -> 11200 | Y7: Debit | AA7: Credit
H8: 3 | J8: J1 | L8: 900 | M8: =M7+K8-L8 -> 10300 | W8: Cash | Y8: 15200
B9: 1 | C9: Eqiument | D9: 157 | E9: 5000 | H9: 4 | J9: J1 | L9: 600 | M9: =M8+K9-L9 -> 9700 | O9: Unearned Serivice Revenue | W9: Supplies | Y9: 2500
C10: Notes payable | D10: 200 | F10: 5000 | H10: 20 | J10: J1 | L10: 500 | M10: =M9+K10-L10 -> 9200 | O10: No. 209 | W10: Prepaid Insurance | Y10: 600
C11: (Isued 3-month,, 12/ note for office) | H11: 26 | J11: J1 | L11: 4000 | M11: =M10+K11-L11 -> 5200 | O11: Date | P11: Explanation | Q11: Ref… | R11: Debit - | S11: Credit + | T11: Balance | W11: Eqiument | Y11: 5000
H12: 31 | J12: J1 | K12: 10000 | M12: =M11+K12-L12 -> 15200 | O12: 2017 Oct. 4 | Q12: J1 | S12: 1200 | T12: =S12 -> 1200 | W12: Notes payable | AA12: 5000
B13: 2 | C13: Cash | D13: 101 | E13: 1200 | W13: Accounts Payable | AA13: 2500
D14: 209 | F14: 1200 | W14: Unearned Serivice Revenue | AA14: 1200
C15: (Received cash from R. Knox for future service) | H15: Supplies | O15: Owner's Capital | W15: Owner's Capital | AA15: 10000
H16: No. 126 | O16: No. 301 | W16: Owner's Drawing | Y16: 500
B17: 3 | C17: Rent Expense | D17: 729 | E17: 900 | H17: Date | I17: Explanation | J17: Ref… | K17: Debit + | L17: Credit - | M17: Balance | O17: Date | P17: Explanation | Q17: Ref… | R17: Debit - | S17: Credit + | T17: Balance | W17: Service Revenue | AA17: 10000
C18: Cash | D18: 101 | F18: 900 | H18: 2017 Oct. 5 | J18: J1 | K18: 2500 | M18: =K18 -> 2500 | O18: 2017 Oct. 4 | Q18: J1 | S18: 10000 | T18: =S18 -> 10000 | W18: Salaries and Wages Expense | Y18: 4000
C19: (Paid October rent) | W19: Rent Expense | Y19: 900
Y20: =SUM(Y8:Y19) -> 28700 | AA20: =SUM(AA8:AA19) -> 28700
B21: 4 | C21: Prepaid Insurance | D21: 130 | E21: 600 | H21: Prepaid Insurance | O21: Owner's Drawings
C22: Cash | D22: 101 | F22: 600 | H22: No. 130 | O22: No. 306
C23: (Paid one-year policy; effective date October 1) | H23: Date | I23: Explanation | J23: Ref… | K23: Debit + | L23: Credit - | M23: Balance | O23: Date | P23: Explanation | Q23: Ref… | R23: Debit + | S23: Credit - | T23: Balance
H24: 2017 Oct. 4 | J24: J1 | K24: 600 | M24: =K24 -> 600 | O24: 2017 Oct. 4 | Q24: J1 | R24: 500 | T24: =R24 -> 500
B25: 5 | C25: Supplies | D25: 126 | E25: 2500
C26: Accounts Payable | D26: 201 | F26: 2500
C27: (Purchased supplies on account from Aero suply) | H27: Eqiument | O27: Service Revenue
H28: No. 157 | O28: No. 400
B29: 20 | C29: Owner's Drawings | D29: 306 | E29: 500 | H29: Date | I29: Explanation | J29: Ref… | K29: Debit + | L29: Credit - | M29: Balance | O29: Date | P29: Explanation | Q29: Ref… | R29: Debit - | S29: Credit + | T29: Balance
C30: Cash | D30: 101 | F30: 500 | H30: 2017 Oct. 4 | J30: J1 | K30: 5000 | M30: =K30 -> 5000 | O30: 2017 Oct. 4 | Q30: J1 | S30: 10000 | T30: =S30 -> 10000
C31: (Withdrew cash for personal use)
B33: 26 | C33: Salaries and Wages Expense | D33: 726 | E33: 4000 | H33: Notes payable | O33: Salaries and Wages Expense
C34: Cash | D34: 101 | F34: 4000 | H34: No. 200 | O34: No. 726
C35: (Paid salaries to date) | H35: Date | I35: Explanation | J35: Ref… | K35: Debit - | L35: Credit + | M35: Balance | O35: Date | P35: Explanation | Q35: Ref… | R35: Debit - | S35: Credit - | T35: Balance
H36: 2017 Oct. 1 | J36: J1 | K36: 5000 | M36: =K36 -> 5000 | O36: 2017 Oct. 4 | Q36: J1 | R36: 4000 | T36: =R36 -> 4000
B37: 31 | C37: Cash | D37: 101 | E37: 10000
C38: Service Revenue | D38: 400 | F38: 10000
C39: (Received cash for servics perforned) | O39: Rent Expense
E40: =SUM(E5:E39) -> 34700 | F40: =SUM(F5:F39) -> 34700 | O40: No. 729
O41: Date | P41: Explanation | Q41: Ref… | R41: Debit + | S41: Credit - | T41: Balance
O42: 2017 Oct. 4 | Q42: J1 | R42: 4000 | T42: =R42 -> 4000

Sheet The Recording Process 2
W2: Assets | AX2: = | AY2: Liabilities | BS2: + | BT2: Owner's Equity
B4: GENERAL JOURNAL | F4: J1 | H4: PIONEER ADVERTISING | P4: Softbyte Inc. | W4: Cash | AD4: Supplies | AK4: Prepaid Insurance | AR4: Eqiument | AY4: Notes payable | BE4: + | BF4: Accounts Payable | BM4: Unearned Serivice Revenue | BS4: + | BT4: Owner's Capital | BZ4: - | CA4: Owner's Drawings | CG4: + | CH4: Service Revenue | CN4: - | CO4: Salaries and Wages Expense
B5: Date | C5: Account Title | D5: Ref… | E5: Debit | F5: Credit | H5: Trial Balance | P5: Income Statement | W5: No. 101 | AD5: No. 126 | AK5: No. 130 | AR5: No. 157 | AY5: No. 200 | BF5: No. 201 | BM5: No. 209 | BT5: No. 301 | CA5: No. 306 | CH5: No. 400 | CO5: No. 726
B6: 2017 Oct. 1 | C6: Cash | D6: 101 | E6: 10000 | H6: October 31,2017 | P6: For the Month Ended September 30,2024 | W6: Date | X6: Explanation | Y6: Ref… | Z6: Debit + | AA6: Credit - | AB6: Balance | AD6: Date | AE6: Explanation | AF6: Ref… | AG6: Debit + | AH6: Credit - | AI6: Balance | AK6: Date | AL6: Explanation | AM6: Ref… | AN6: Debit + | AO6: Credit - | AP6: Balance | AR6: Date | AS6: Explanation | AT6: Ref… | AU6: Debit + | AV6: Credit - | AW6: Balance | AY6: Date | AZ6: Explanation | BA6: Ref… | BB6: Debit - | BC6: Credit + | BD6: Balance | BF6: Date | BG6: Explanation | BH6: Ref… | BI6: Debit - | BJ6: Credit + | BK6: Balance | BM6: Date | BN6: Explanation | BO6: Ref… | BP6: Debit - | BQ6: Credit + | BR6: Balance | BT6: Date | BU6: Explanation | BV6: Ref… | BW6: Debit - | BX6: Credit + | BY6: Balance | CA6: Date | CB6: Explanation | CC6: Ref… | CD6: Debit + | CE6: Credit - | CF6: Balance | CH6: Date | CI6: Explanation | CJ6: Ref… | CK6: Debit - | CL6: Credit + | CM6: Balance | CO6: Date | CP6: Explanation | CQ6: Ref… | CR6: Debit + | CS6: Credit - | CT6: Balance
C7: Owner's Capital | D7: 301 | F7: 10000 | W7: 2017 Oct. 1 | Y7: =F4 -> J1 | Z7: =E6 -> 10000 | AB7: =Z7 -> 10000 | AD7: 2017 Oct. 5 | AF7: J1 | AG7: =E26 -> 2500 | AI7: =AG7 -> 2500 | AK7: 2017 Oct. 4 | AM7: J1 | AN7: =E22 -> 600 | AP7: =AN7 -> 600 | AR7: 2017 Oct. 4 | AT7: J1 | AU7: =E10 -> 5000 | AW7: =AU7 -> 5000 | AY7: 2017 Oct. 1 | BA7: J1 | BC7: =F11 -> 5000 | BD7: =BC7 -> 5000 | BF7: 2017 Oct. 4 | BH7: J1 | BJ7: =F27 -> 2500 | BK7: =BJ7 -> 2500 | BM7: 2017 Oct. 4 | BO7: J1 | BQ7: =F15 -> 1200 | BR7: =BQ7 -> 1200 | BT7: 2017 Oct. 4 | BV7: J1 | BX7: =F7 -> 10000 | BY7: =BX7 -> 10000 | CA7: 2017 Oct. 4 | CC7: J1 | CD7: =E30 -> 500 | CF7: =CD7 -> 500 | CH7: 2017 Oct. 4 | CJ7: J1 | CL7: =F39 -> 10000 | CM7: =CL7 -> 10000 | CO7: 2017 Oct. 4 | CQ7: J1 | CR7: =E34 -> 4000 | CT7: =CR7 -> 4000
C8: (Owner's investment of cash in business) | J8: Debit | L8: Credit | Q8: Revenues | W8: 2 | Y8: =F4 -> J1 | Z8: =E14 -> 1200 | AB8: =AB7+Z8-AA8 -> 11200 | AI8: =AI7+AG8-AH8 -> 2500 | AP8: =AP7+AN8-AO8 -> 600 | AW8: =AW7+AU8-AV8 -> 5000 | BD8: =BD7+BC8-BB8 -> 5000 | BK8: =BK7+BJ8-BI8 -> 2500 | BR8: =BR7+BQ8-BO8 -> 1200 | BY8: =BY7+BX8-BW8 -> 10000 | CF8: =CF7+CD8-CE8 -> 500 | CT8: =CT7+CR8-CS8 -> 4000
I9: Cash | J9: =AB14 -> 15200 | R9: Serive Revenue | T9: =L18 -> 10000 | W9: 3 | Y9: =F4 -> J1 | AA9: =F19 -> 900 | AB9: =AB8+Z9-AA9 -> 10300 | AG9: =SUM(AG7:AG8) -> 2500 | AH9: =SUM(AH7:AH8) -> 0 | AI9: =AI8 -> 2500 | AN9: =SUM(AN7:AN8) -> 600 | AO9: =SUM(AO7:AO8) -> 0 | AP9: =AP8 -> 600 | AU9: =SUM(AU7:AU8) -> 5000 | AV9: =SUM(AV7:AV8) -> 0 | AW9: =AW8 -> 5000 | BB9: =SUM(BB7:BB8) -> 0 | BC9: =SUM(BC7:BC8) -> 5000 | BD9: =BD8 -> 5000 | BI9: =SUM(BI2:BI8) -> 0 | BJ9: =SUM(BJ2:BJ8) -> 2500 | BK9: =BK8 -> 2500 | BP9: =SUM(BP7:BP8) -> 0 | BQ9: =SUM(BQ7:BQ8) -> 1200 | BR9: =BR8 -> 1200 | BW9: =SUM(BW7:BW8) -> 0 | BX9: =SUM(BX7:BX8) -> 10000 | BY9: =BY8 -> 10000 | CD9: =SUM(CD7:CD8) -> 500 | CE9: =SUM(CE7:CE8) -> 0 | CF9: =CF8 -> 500 | CK9: =SUM(CK6:CK7) -> 0 | CL9: =SUM(CL6:CL7) -> 10000 | CM9: =CM7 -> 10000 | CR9: =SUM(CR7:CR8) -> 4000 | CS9: =SUM(CS7:CS8) -> 0 | CT9: =CT8 -> 4000
B10: 1 | C10: Eqiument | D10: 157 | E10: 5000 | I10: Supplies | J10: =AI9 -> 2500 | Q10: Expense | W10: 4 | Y10: =F4 -> J1 | AA10: =F23 -> 600 | AB10: =AB9+Z10-AA10 -> 9700
C11: Notes payable | D11: 200 | F11: 5000 | I11: Prepaid Insurance | J11: =AP9 -> 600 | R11: Salaries and Wages expense | S11: =J19 -> 4000 | W11: 20 | Y11: =F4 -> J1 | AA11: =F31 -> 500 | AB11: =AB10+Z11-AA11 -> 9200 | CO11: Rent Expense
C12: (Isued 3-month,, 12/ note for office) | I12: Eqiument | J12: =AW9 -> 5000 | R12: Supplies Expense | S12: =J20 -> 900 | W12: 26 | Y12: =F4 -> J1 | AA12: =F35 -> 4000 | AB12: =AB11+Z12-AA12 -> 5200 | CO12: No. 729
I13: Notes payable | L13: =BD9 -> 5000 | R13: Total Expense | T13: =S11+S12 -> 4900 | W13: 31 | Y13: =F4 -> J1 | Z13: =E38 -> 10000 | AB13: =AB12+Z13-AA13 -> 15200 | CO13: Date | CP13: Explanation | CQ13: Ref… | CR13: Debit + | CS13: Credit - | CT13: Balance
B14: 2 | C14: Cash | D14: 101 | E14: 1200 | I14: Accounts Payable | L14: =BK9 -> 2500 | Q14: Net income | T14: =T9-T13 -> 5100 | Z14: =SUM(Z7:Z13) -> 21200 | AA14: =SUM(AA7:AA13) -> 6000 | AB14: =AB13 -> 15200 | CO14: 2017 Oct. 4 | CQ14: J1 | CR14: =E18 -> 900 | CT14: =CR14 -> 900
C15: Unearned Serivice Revenue | D15: 209 | F15: 1200 | I15: Unearned Serivice Revenue | L15: =BR9 -> 1200 | CT15: =CT14+CR15-CS15 -> 900
C16: (Received cash from R. Knox for future service) | I16: Owner's Capital | L16: =BY9 -> 10000 | CR16: =SUM(CR14:CR15) -> 900 | CS16: =SUM(CS14:CS15) -> 0 | CT16: =CT15 -> 900
I17: Owner's Drawing | J17: =CF9 -> 500 | P17: Softbyte Inc.
B18: 3 | C18: Rent Expense | D18: 729 | E18: 900 | I18: Service Revenue | L18: =CM9 -> 10000 | P18: Retained Ernings Statement
C19: Cash | D19: 101 | F19: 900 | I19: Salaries and Wages Expense | J19: =CT9 -> 4000 | P19: For the Month Ended September 30,204
C20: (Paid October rent) | I20: Rent Expense | J20: =CT16 -> 900
J21: =SUM(J9:J20) -> 28700 | L21: =SUM(L9:L20) -> 28700 | R21: Retined earinihg, September 1 | T21: 0
B22: 4 | C22: Prepaid Insurance | D22: 130 | E22: 600 | R22: Add: Investments | T22: 15000
C23: Cash | D23: 101 | F23: 600
C24: (Paid one-year policy; effective date October 1) | R24: Net Income | T24: =T14 -> 5100
B26: 5 | C26: Supplies | D26: 126 | E26: 2500 | R26: Owner's drawings | T26: =J17 -> 500
C27: Accounts Payable | D27: 201 | F27: 2500 | R27: Owner's capital October 31 | T27: =T22+T24-T26 -> 19600
C28: (Purchased supplies on account from Aero suply)
B30: 20 | C30: Owner's Drawings | D30: 306 | E30: 500 | P30: Softbyte Inc.
C31: Cash | D31: 101 | F31: 500 | P31: Balance Sheet
C32: (Withdrew cash for personal use) | P32: For the Month Ended September 30,204
P33: Assets
B34: 26 | C34: Salaries and Wages Expense | D34: 726 | E34: 4000 | Q34: Cash | T34: ='The Recording Process 2'!J9 -> 15200
C35: Cash | D35: 101 | F35: 4000 | Q35: Supplies | T35: ='The Recording Process 2'!J10 -> 2500
C36: (Paid salaries to date) | Q36: Prepaid Insurance | T36: ='The Recording Process 2'!J11 -> 600
Q37: Eqiument | T37: ='The Recording Process 2'!J12 -> 5000
B38: 31 | C38: Cash | D38: 101 | E38: 10000 | Q38: Total Assets | T38: =SUM(T34:T37) -> 23300
C39: Service Revenue | D39: 400 | F39: 10000
C40: (Received cash for servics perforned) | P40: Liabilities
E41: =SUM(E6:E40) -> 34700 | F41: =SUM(F6:F40) -> 34700 | Q41: Notes payable | T41: ='The Recording Process 2'!L13 -> 5000
Q42: Accounts Payable | T42: ='The Recording Process 2'!L14 -> 2500
Q43: Unearned Serivice Revenue | T43: ='The Recording Process 2'!L15 -> 1200
Q44: Total Liabilities | T44: =SUM(T41:T43) -> 8700
...

Sheet Adjusting the Accounts 3
AC2: Assets | BD2: = | BE2: Liabilities | BY2: + | BZ2: Owner's Equity
B4: GENERAL JOURNAL | F4: J1 | H4: GENERAL JOURNAL | L4: J2 | N4: PIONEER ADVERTISING | V4: Softbyte Inc. | AC4: Cash | AJ4: Supplies | AQ4: Prepaid Insurance | AX4: Eqiument | BE4: Notes payable | BK4: + | BL4: Accounts Payable | BS4: Unearned Serivice Revenue | BY4: + | BZ4: Owner's Capital | CF4: - | CG4: Owner's Drawings | CM4: + | CN4: Service Revenue | CT4: - | CU4: Salaries and Wages Expense
B5: Date | C5: Account Title | D5: Ref… | E5: Debit | F5: Credit | H5: Date | I5: Account Title | J5: Ref… | K5: Debit | L5: Credit | N5: Trial Balance | V5: Income Statement | AC5: No. 101 | AJ5: No. 126 | AQ5: No. 130 | AX5: No. 157 | BE5: No. 200 | BL5: No. 201 | BS5: No. 209 | BZ5: No. 301 | CG5: No. 306 | CN5: No. 400 | CU5: No. 726
B6: 2017 Oct. 1 | C6: Cash | D6: 101 | E6: 10000 | I6: Adjusting Entries | N6: October 31,2017 | V6: For the Month Ended September 30,2024 | AC6: Date | AD6: Explanation | AE6: Ref… | AF6: Debit + | AG6: Credit - | AH6: Balance | AJ6: Date | AK6: Explanation | AL6: Ref… | AM6: Debit + | AN6: Credit - | AO6: Balance | AQ6: Date | AR6: Explanation | AS6: Ref… | AT6: Debit + | AU6: Credit - | AV6: Balance | AX6: Date | AY6: Explanation | AZ6: Ref… | BA6: Debit + | BB6: Credit - | BC6: Balance | BE6: Date | BF6: Explanation | BG6: Ref… | BH6: Debit - | BI6: Credit + | BJ6: Balance | BL6: Date | BM6: Explanation | BN6: Ref… | BO6: Debit - | BP6: Credit + | BQ6: Balance | BS6: Date | BT6: Explanation | BU6: Ref… | BV6: Debit - | BW6: Credit + | BX6: Balance | BZ6: Date | CA6: Explanation | CB6: Ref… | CC6: Debit - | CD6: Credit + | CE6: Balance | CG6: Date | CH6: Explanation | CI6: Ref… | CJ6: Debit + | CK6: Credit - | CL6: Balance | CN6: Date | CO6: Explanation | CP6: Ref… | CQ6: Debit - | CR6: Credit + | CS6: Balance | CU6: Date | CV6: Explanation | CW6: Ref… | CX6: Debit + | CY6: Credit - | CZ6: Balance
C7: Owner's Capital | D7: 301 | F7: 10000 | H7: Oct. 31 | I7: Supplies Expense | J7: 631 | K7: 1500 | AC7: 2017 Oct. 1 | AE7: =F4 -> J1 | AF7: =E6 -> 10000 | AH7: =AF7 -> 10000 | AJ7: 2017 Oct. 5 | AL7: J1 | AM7: =E26 -> 2500 | AO7: =AM7 -> 2500 | AQ7: 2017 Oct. 4 | AS7: J1 | AT7: =E22 -> 600 | AV7: =AT7 -> 600 | AX7: 2017 Oct. 4 | AZ7: J1 | BA7: =E10 -> 5000 | BC7: =BA7 -> 5000 | BE7: 2017 Oct. 1 | BG7: J1 | BI7: =F11 -> 5000 | BJ7: =BI7 -> 5000 | BL7: 2017 Oct. 4 | BN7: J1 | BP7: =F27 -> 2500 | BQ7: =BP7 -> 2500 | BS7: 2017 Oct. 4 | BU7: J1 | BW7: =F15 -> 1200 | BX7: =BW7 -> 1200 | BZ7: 2017 Oct. 4 | CB7: J1 | CD7: =F7 -> 10000 | CE7: =CD7 -> 10000 | CG7: 2017 Oct. 4 | CI7: J1 | CJ7: =E30 -> 500 | CL7: =CJ7 -> 500 | CN7: 2017 Oct. 4 | CP7: J1 | CR7: =F39 -> 10000 | CS7: =CR7 -> 10000 | CU7: 2017 Oct. 4 | CW7: J1 | CX7: =E34 -> 4000 | CZ7: =CX7 -> 4000
C8: (Owner's investment of cash in business) | I8: Supplies | J8: 126 | L8: 1500 | P8: Debit | R8: Credit | W8: Revenues | AC8: 2 | AE8: =F4 -> J1 | AF8: =E14 -> 1200 | AH8: =AH7+AF8-AG8 -> 11200 | AJ8: 2017 Oct. 31 | AK8: Adj.entry | AL8: j2 | AN8: 1500 | AO8: =AO7+AM8-AN8 -> 1000 | AQ8: 2017 Oct. 31 | AR8: Adj.entry | AS8: j2 | AU8: 50 | AV8: =AV7+AT8-AU8 -> 550 | BC8: =BC7+BA8-BB8 -> 5000 | BJ8: =BJ7+BI8-BH8 -> 5000 | BQ8: =BQ7+BP8-BO8 -> 2500 | BX8: =BX7+BW8-BU8 -> 1200 | CE8: =CE7+CD8-CC8 -> 10000 | CL8: =CL7+CJ8-CK8 -> 500 | CN8: 2017 Oct. 31 | CO8: Adj.entry | CP8: j2 | CR8: 400 | CS8: =CS7+CR8-CQ8 -> 10400 | CZ8: =CZ7+CX8-CY8 -> 4000
I9: (To record supplies used) | O9: Cash | P9: =AH14 -> 15200 | X9: Serive Revenue | Z9: =R22 -> 10600 | AC9: 3 | AE9: =F4 -> J1 | AG9: =F19 -> 900 | AH9: =AH8+AF9-AG9 -> 10300 | AM9: =SUM(AM7:AM8) -> 2500 | AN9: =SUM(AN7:AN8) -> 1500 | AO9: =AO8 -> 1000 | AT9: =SUM(AT7:AT8) -> 600 | AU9: =SUM(AU7:AU8) -> 50 | AV9: =AV8 -> 550 | BA9: =SUM(BA7:BA8) -> 5000 | BB9: =SUM(BB7:BB8) -> 0 | BC9: =BC8 -> 5000 | BH9: =SUM(BH7:BH8) -> 0 | BI9: =SUM(BI7:BI8) -> 5000 | BJ9: =BJ8 -> 5000 | BO9: =SUM(BO7:BO8) -> 0 | BP9: =SUM(BP7:BP8) -> 2500 | BQ9: =BQ8 -> 2500 | BV9: =SUM(BV7:BV8) -> 0 | BW9: =SUM(BW7:BW8) -> 1200 | BX9: =BX8 -> 1200 | CC9: =SUM(CC7:CC8) -> 0 | CD9: =SUM(CD7:CD8) -> 10000 | CE9: =CE8 -> 10000 | CJ9: =SUM(CJ7:CJ8) -> 500 | CK9: =SUM(CK7:CK8) -> 0 | CL9: =CL8 -> 500 | CN9: 2017 Oct. 31 | CO9: Adj.entry | CP9: j2 | CR9: 200 | CS9: =CS8+CR9-CQ9 -> 10600 | CX9: =SUM(CX7:CX8) -> 4000 | CY9: =SUM(CY7:CY8) -> 0 | CZ9: =CZ8 -> 4000
B10: 1 | C10: Eqiument | D10: 157 | E10: 5000 | O10: Accounts Receivable | P10: =AV16 -> 200 | W10: Expense | AC10: 4 | AE10: =F4 -> J1 | AG10: =F23 -> 600 | AH10: =AH9+AF10-AG10 -> 9700 | CQ10: =SUM(CQ6:CQ7) -> 0 | CR10: =SUM(CR6:CR7) -> 10000 | CS10: =CS9 -> 10600
C11: Notes payable | D11: 200 | F11: 5000 | H11: 31 | I11: Insurance Expense | J11: 722 | K11: 50 | O11: Supplies | P11: =AO9 -> 1000 | X11: Salaries and Wages expense | Y11: =P23 -> 5200 | AC11: 20 | AE11: =F4 -> J1 | AG11: =F31 -> 500 | AH11: =AH10+AF11-AG11 -> 9200 | AQ11: Accounts Receivable | BL11: Interest Payable | CU11: Rent Expense
C12: (Isued 3-month,, 12/ note for office) | I12: Prepaid Insurance | J12: 130 | L12: 50 | O12: Prepaid Insurance | P12: =AV9 -> 550 | X12: Supplies Expense | Y12: =P24 -> 1500 | AC12: 26 | AE12: =F4 -> J1 | AG12: =F35 -> 4000 | AH12: =AH11+AF12-AG12 -> 5200 | AQ12: No. 112 | BL12: No. 230 | CU12: No. 729
I13: (To record insurance expired ) | O13: Eqiument | P13: =BC9 -> 5000 | X13: Rent Expense | Y13: =P25 -> 900 | AC13: 31 | AE13: =F4 -> J1 | AF13: =E38 -> 10000 | AH13: =AH12+AF13-AG13 -> 15200 | AQ13: Date | AR13: Explanation | AS13: Ref… | AT13: Debit + | AU13: Credit - | AV13: Balance | BL13: Date | BM13: Explanation | BN13: Ref… | BO13: Debit - | BP13: Credit + | BQ13: Balance | CU13: Date | CV13: Explanation | CW13: Ref… | CX13: Debit + | CY13: Credit - | CZ13: Balance
B14: 2 | C14: Cash | D14: 101 | E14: 1200 | O14: Accumulateted Depercation---Eqiupment | R14: =AO23 -> 40 | X14: Insurance Expense | Y14: =P26 -> 50 | AF14: =SUM(AF7:AF13) -> 21200 | AG14: =SUM(AG7:AG13) -> 6000 | AH14: =AH13 -> 15200 | AQ14: 2017 Oct. 31 | AR14: Adj.entry | AS14: j2 | AT14: 200 | AV14: =AT14 -> 200 | BL14: 2017 Oct. 31 | BM14: Adj.entry | BN14: j2 | BP14: 50 | BQ14: =BP14 -> 50 | CU14: 2017 Oct. 4 | CW14: J1 | CX14: =E18 -> 900 | CZ14: =CX14 -> 900
C15: Unearned Serivice Revenue | D15: 209 | F15: 1200 | H15: 31 | I15: Depercation Expense | J15: 711 | K15: 40 | O15: Notes payable | R15: =BJ9 -> 5000 | X15: Interest Expense | Y15: =P27 -> 50 | AV15: =AV14+AT15-AU15 -> 200 | BQ15: =BQ14+BP15-BO15 -> 50 | CZ15: =CZ14+CX15-CY15 -> 900
C16: (Received cash from R. Knox for future service) | I16: Accumulateted--Depercation Expense | J16: 158 | L16: 40 | O16: Accounts Payable | R16: =BQ9 -> 2500 | X16: Depercation Expense | Y16: =P28 -> 40 | AT16: =SUM(AT14:AT15) -> 200 | AU16: =SUM(AU14:AU15) -> 0 | AV16: =AV15 -> 200 | BO16: =SUM(BO14:BO15) -> 0 | BP16: =SUM(BP14:BP15) -> 50 | BQ16: =BQ15 -> 50 | CX16: =SUM(CX14:CX15) -> 900 | CY16: =SUM(CY14:CY15) -> 0 | CZ16: =CZ15 -> 900
I17: (To record monthly depreciation) | O17: Interest payable | R17: =BQ16 -> 50 | X17: Total Expense | Z17: =SUM(Y11:Y16) -> 7740
B18: 3 | C18: Rent Expense | D18: 729 | E18: 900 | O18: Unearned Serivice Revenue | R18: =CZ44 -> 800 | W18: Net income | Z18: =Z9-Z17 -> 2860 | AJ18: Accumulateted--Depercation Eqiument | BL18: Salaries and Wages Payable | CU18: Insurance Expense
C19: Cash | D19: 101 | F19: 900 | H19: 31 | I19: Unearned Serivice Revenue | J19: 209 | K19: 400 | O19: Salaries and Wages payable | R19: ='Adjusting the Accounts 3'!BQ23 -> 1200 | AJ19: No. 158 | BL19: No. 212 | CU19: No. 722
C20: (Paid October rent) | I20: Service Revenue | J20: 400 | L20: 400 | O20: Owner's Capital | R20: =CE9 -> 10000 | AJ20: Date | AK20: Explanation | AL20: Ref… | AM20: Debit + | AN20: Credit - | AO20: Balance | BL20: Date | BM20: Explanation | BN20: Ref… | BO20: Debit + | BP20: Credit - | BQ20: Balance | CU20: Date | CV20: Explanation | CW20: Ref… | CX20: Debit + | CY20: Credit - | CZ20: Balance
I21: (To record interest on motes payable) | O21: Owner's Capital | P21: =CL9 -> 500 | V21: Softbyte Inc. | AJ21: 2017 Oct. 31 | AK21: Adj.entry | AL21: j2 | AN21: 40 | AO21: =AN21 -> 40 | BL21: 2017 Oct. 31 | BM21: Adj.entry | BN21: j2 | BP21: 1200 | BQ21: =BP21 -> 1200 | CU21: 2017 Oct. 31 | CV21: Adj.entry | CW21: j2 | CX21: 50 | CZ21: =CX21 -> 50
B22: 4 | C22: Prepaid Insurance | D22: 130 | E22: 600 | O22: Service Revenue | R22: =CS10 -> 10600 | V22: Retained Ernings Statement | AO22: =AO21+AM22-AN22 -> 40 | BQ22: =BQ21+BO22-BP22 -> 1200 | CZ22: =CZ21+CX22-CY22 -> 50
C23: Cash | D23: 101 | F23: 600 | H23: 31 | I23: Accounts Receivable | J23: 112 | K23: 200 | O23: Salaries and Wages Expense | P23: =CZ30 -> 5200 | V23: For the Month Ended September 30,204 | AM23: =SUM(AM21:AM22) -> 0 | AN23: =SUM(AN21:AN22) -> 40 | AO23: =AO22 -> 40 | BO23: =SUM(BO21:BO22) -> 0 | BP23: =SUM(BP21:BP22) -> 1200 | BQ23: =BQ22 -> 1200 | CX23: =SUM(CX21:CX22) -> 50 | CY23: =SUM(CY21:CY22) -> 0 | CZ23: =CZ22 -> 50
C24: (Paid one-year policy; effective date October 1) | I24: Service Revenue | J24: 400 | L24: 200 | O24: Supplies Expense | P24: =CZ58 -> 1500
I25: (To record revevue for services performed) | O25: Rent Expense | P25: =CZ16 -> 900 | X25: Retined earinihg, September 1 | Z25: 0 | CU25: Salaries and Wages Expense
B26: 5 | C26: Supplies | D26: 126 | E26: 2500 | O26: Insurance Expense | P26: =CZ23 -> 50 | X26: Add: Investments | Z26: 10000 | CU26: No. 726
C27: Accounts Payable | D27: 201 | F27: 2500 | H27: 31 | I27: Interest Expense | J27: 905 | K27: 50 | O27: Interest Expense | P27: =CZ37 -> 50 | CU27: Date | CV27: Explanation | CW27: Ref… | CX27: Debit + | CY27: Credit - | CZ27: Balance
C28: (Purchased supplies on account from Aero suply) | I28: Interest Payable | J28: 230 | L28: 50 | O28: Depercation Expense | P28: =CZ51 -> 40 | X28: Net Income | Z28: =Z18 -> 2860 | CU28: 2017 Oct. 4 | CW28: J1 | CX28: 4000 | CZ28: =CX28 -> 4000
I29: (To record interest on notes payable) | P29: =SUM(P9:P28) -> 30190 | R29: =SUM(R9:R29) -> 30190 | CU29: 2017 Oct. 31 | CV29: ` | CW29: j2 | CX29: 1200 | CZ29: =CZ28+CX29-CY29 -> 5200
B30: 20 | C30: Owner's Drawings | D30: 306 | E30: 500 | X30: Owner's drawings | Z30: =P21 -> 500 | CX30: =SUM(CX28:CX29) -> 5200 | CY30: =SUM(CY28:CY29) -> 0 | CZ30: =CZ29 -> 5200
C31: Cash | D31: 101 | F31: 500 | H31: 26 | I31: Salaries and Wages Expense | J31: 726 | K31: 1200 | X31: Owner's capital October 31 | Z31: =Z26+Z28-Z30 -> 12360
C32: (Withdrew cash for personal use) | I32: Salaries and Wages Payable | J32: 212 | L32: 1200 | CU32: Interest Expense
I33: (To record accrued salaries and wages) | CU33: No. 905
B34: 26 | C34: Salaries and Wages Expense | D34: 726 | E34: 4000 | V34: Softbyte Inc. | CU34: Date | CV34: Explanation | CW34: Ref… | CX34: Debit + | CY34: Credit - | CZ34: Balance
C35: Cash | D35: 101 | F35: 4000 | K35: =SUM(K7:K34) -> 3440 | L35: =SUM(L7:L34) -> 3440 | V35: Balance Sheet | CU35: 2017 Oct. 31 | CV35: ` | CW35: j2 | CX35: 50 | CZ35: =CX35 -> 50
C36: (Paid salaries to date) | V36: For the Month Ended September 30,204 | CZ36: =CZ35+CX36-CY36 -> 50
V37: Assets | CX37: =SUM(CX35:CX36) -> 50 | CY37: =SUM(CY35:CY36) -> 0 | CZ37: =CZ36 -> 50
B38: 31 | C38: Cash | D38: 101 | E38: 10000 | W38: Cash | Z38: ='The Recording Process 2'!J9 -> 15200
C39: Service Revenue | D39: 400 | F39: 10000 | W39: Accounts Receivable | Z39: =P10 -> 200 | CU39: Unearned Serivice Revenue
C40: (Received cash for servics perforned) | W40: Supplies | Z40: =P11 -> 1000 | CU40: No. 209
E41: =SUM(E6:E40) -> 34700 | F41: =SUM(F6:F40) -> 34700 | W41: Prepaid Insurance | Z41: =P12 -> 550 | CU41: Date | CV41: Explanation | CW41: Ref… | CX41: Debit - | CY41: Credit + | CZ41: Balance
W42: Eqiument | Z42: =P13 -> 5000 | CU42: 2017 Oct. 4 | CW42: J1 | CY42: 1200 | CZ42: =CY42 -> 1200
...

Sheet 3
B3: GENERAL JOURNAL | F3: J2 | H3: Cash | O3: Interest Payable | V3: PIONEER ADVERTISING | AC3: Softbyte Inc.
B4: Date | C4: Account Title | D4: Ref… | E4: Debit | F4: Credit | H4: No. 101 | O4: No. 230 | V4: Adjusted Trial Balance | AC4: Income Statement
C5: Adjusting Entries | H5: Date | I5: Explanation | J5: Ref… | K5: Debit + | L5: Credit - | M5: Balance | O5: Date | P5: Explanation | Q5: Ref… | R5: Debit - | S5: Credit + | T5: Balance | V5: October 31,2017 | AC5: For the Month Ended September 30,2024
B6: Oct. 31 | C6: Supplies Expense | D6: 631 | E6: 1500 | H6: 2017 Oct. 1 | J6: J1 | K6: 10000 | M6: =K6 -> 10000 | O6: 2017 Oct. 31 | P6: Adj.entry | Q6: j2 | S6: 50 | T6: =S6 -> 50
C7: Supplies | D7: 126 | F7: 1500 | H7: 2 | J7: J1 | K7: 1200 | M7: =M6+K7-L7 -> 11200 | X7: Debit | Z7: Credit | AD7: Revenues
C8: (To record supplies used) | H8: 3 | J8: J1 | L8: 900 | M8: =M7+K8-L8 -> 10300 | W8: Cash | X8: 15200 | AE8: Serive Revenue | AG8: 10600
H9: 4 | J9: J1 | L9: 600 | M9: =M8+K9-L9 -> 9700 | O9: Owner's Capital | W9: Accounts Receivable | X9: 200 | AD9: Expense
B10: 31 | C10: Insurance Expense | D10: 722 | E10: 50 | H10: 20 | J10: J1 | L10: 500 | M10: =M9+K10-L10 -> 9200 | O10: No. 301 | W10: Supplies | X10: 1000 | AE10: Salaries and Wages expense | AF10: 5200
C11: Prepaid Insurance | D11: 130 | F11: 50 | H11: 26 | J11: J1 | L11: 4000 | M11: =M10+K11-L11 -> 5200 | O11: Date | P11: Explanation | Q11: Ref… | R11: Debit - | S11: Credit + | T11: Balance | W11: Prepaid Insurance | X11: 550 | AE11: Supplies Expense | AF11: 1500
C12: (To record insurance expired ) | H12: 31 | J12: J1 | K12: 10000 | M12: =M11+K12-L12 -> 15200 | O12: 2017 Oct. 4 | Q12: J1 | S12: 10000 | T12: =S12 -> 10000 | W12: Eqiument | X12: 5000 | AE12: Rent Expense | AF12: 900
W13: Accumulateted Depercation---Eqiupment | Z13: 40 | AE13: Insurance Expense | AF13: 50
B14: 31 | C14: Depercation Expense | D14: 711 | E14: 40 | W14: Notes payable | Z14: 5000 | AE14: Interest Expense | AF14: 50
C15: Accumulateted--Depercation Expense | D15: 158 | F15: 40 | H15: Accounts Receivable | O15: Owner's Drawings | W15: Accounts Payable | Z15: 2500 | AE15: Depercation Expense | AF15: 40
C16: (To record monthly depreciation) | H16: No. 112 | O16: No. 306 | W16: Interest payable | Z16: 50
H17: Date | I17: Explanation | J17: Ref… | K17: Debit + | L17: Credit - | M17: Balance | O17: Date | P17: Explanation | Q17: Ref… | R17: Debit + | S17: Credit - | T17: Balance | W17: Unearned Serivice Revenue | Z17: 800 | AE17: Total Expense | AG17: =SUM(AF10:AF16) -> 7740
B18: 31 | C18: Unearned Serivice Revenue | D18: 209 | E18: 400 | H18: 2017 Oct. 31 | I18: Adj.entry | J18: j2 | K18: 200 | M18: =K18 -> 200 | O18: 2017 Oct. 4 | Q18: J1 | R18: 500 | T18: =R18 -> 500 | W18: Salaries and Wages payable | Z18: 1200 | AD18: Net income | AG18: =AG8-AG17 -> 2860
C19: Service Revenue | D19: 400 | F19: 400 | W19: Owner's Capital | Z19: 10000
C20: (To record interest on motes payable) | W20: Owner's Drawings | X20: 500
H21: Supplies | O21: Service Revenue | W21: Service Revenue | Z21: 10600 | AC21: Softbyte Inc.
B22: 31 | C22: Accounts Receivable | D22: 112 | E22: 200 | H22: No. 126 | O22: No. 400 | W22: Salaries and Wages Expense | X22: 5200 | AC22: Retained Ernings Statement
C23: Service Revenue | D23: 400 | F23: 200 | H23: Date | I23: Explanation | J23: Ref… | K23: Debit + | L23: Credit - | M23: Balance | O23: Date | P23: Explanation | Q23: Ref… | R23: Debit - | S23: Credit + | T23: Balance | W23: Supplies Expense | X23: 1500 | AC23: For the Month Ended September 30,204
C24: (To record revevue for services performed) | H24: 2017 Oct. 5 | J24: J1 | K24: 2500 | M24: =K24 -> 2500 | O24: 2017 Oct. 4 | Q24: J1 | S24: 10000 | T24: =S24 -> 10000 | W24: Rent Expense | X24: 900
H25: 2017 Oct. 31 | I25: Adj.entry | J25: j2 | L25: 1500 | M25: =M24+K25-L25 -> 1000 | O25: 2017 Oct. 31 | P25: Adj.entry | Q25: j2 | S25: 400 | T25: =S25 -> 400 | W25: Insurance Expense | X25: 50 | AD25: Retined earinihg, September 1 | AG25: 0
B26: 31 | C26: Interest Expense | D26: 905 | E26: 50 | O26: 2017 Oct. 31 | P26: Adj.entry | Q26: j2 | S26: 200 | T26: =S26 -> 200 | W26: Interest Expense | X26: 50 | AD26: Add: Investments | AG26: 10000
C27: Interest Payable | D27: 230 | F27: 50 | H27: Prepaid Insurance | W27: Depercation Expense | X27: 40 | AG27: 10000
C28: (To record interest on notes payable) | H28: No. 130 | O28: Supplies Expense | AD28: Net Income | AG28: 2860
H29: Date | I29: Explanation | J29: Ref… | K29: Debit + | L29: Credit - | M29: Balance | O29: No. 631 | X29: =SUM(X8:X28) -> 30190 | Z29: =SUM(Z8:Z28) -> 30190 | AG29: 12860
B30: 26 | C30: Salaries and Wages Expense | D30: 726 | E30: 1200 | H30: 2017 Oct. 4 | J30: J1 | K30: 600 | M30: =K30 -> 600 | O30: Date | P30: Explanation | Q30: Ref… | R30: Debit + | S30: Credit - | T30: Balance | AD30: Owner's drawings | AG30: 500
C31: Salaries and Wages Payable | D31: 212 | F31: 1200 | H31: 2017 Oct. 31 | I31: Adj.entry | J31: j2 | L31: 50 | M31: =M30+K31-L31 -> 550 | O31: 2017 Oct. 31 | P31: Adj.entry | Q31: j2 | R31: 1500 | T31: =R31 -> 1500 | AD31: Owner's capital October 31 | AG31: 12360
C32: (To record accrued salaries and wages)
H33: Eqiument
E34: =SUM(E6:E33) -> 3440 | F34: =SUM(F6:F33) -> 3440 | H34: No. 157 | AC34: Softbyte Inc.
H35: Date | I35: Explanation | J35: Ref… | K35: Debit + | L35: Credit - | M35: Balance | AC35: Balance Sheet
H36: 2017 Oct. 4 | J36: J1 | K36: 5000 | M36: =K36 -> 5000 | AC36: For the Month Ended September 30,204
AC37: Assets
AD38: Cash | AG38: 15200
H39: Accumulateted--Depercation Eqiument | AD39: Accounts Receivable | AG39: 200
H40: No. 158 | O40: Insurance Expense | AD40: Supplies | AG40: 1000
H41: Date | I41: Explanation | J41: Ref… | K41: Debit + | L41: Credit - | M41: Balance | O41: No. 722 | AD41: Prepaid Insurance | AG41: 550
H42: 2017 Oct. 31 | I42: Adj.entry | J42: j2 | L42: 40 | M42: =L42 -> 40 | O42: Date | P42: Explanation | Q42: Ref… | R42: Debit + | S42: Credit - | T42: Balance | AD42: Eqiument | AF42: 5000
...

Sheet 4
AI2: Assets | BJ2: = | BK2: Liabilities | CE2: + | CF2: Owner's Equity
B4: GENERAL JOURNAL | F4: J1 | H4: GENERAL JOURNAL | L4: J2 | N4: GENERAL JOURNAL | R4: J3 | T4: PIONEER ADVERTISING | AB4: Softbyte Inc. | AI4: Cash | AP4: Supplies | AW4: Prepaid Insurance | BD4: Eqiument | BK4: Notes payable | BQ4: + | BR4: Accounts Payable | BY4: Unearned Serivice Revenue | CE4: + | CF4: Owner's Capital | CL4: - | CM4: Owner's Drawings | CS4: + | CT4: Service Revenue | CZ4: - | DA4: Salaries and Wages Expense
B5: Date | C5: Account Title | D5: Ref… | E5: Debit | F5: Credit | H5: Date | I5: Account Title | J5: Ref… | K5: Debit | L5: Credit | N5: Date | O5: Account Title | P5: Ref… | Q5: Debit | R5: Credit | T5: Trial Balance | AB5: Income Statement | AI5: No. 101 | AP5: No. 126 | AW5: No. 130 | BD5: No. 157 | BK5: No. 200 | BR5: No. 201 | BY5: No. 209 | CF5: No. 301 | CM5: No. 306 | CT5: No. 400 | DA5: No. 726
B6: 2017 Oct. 1 | C6: Cash | D6: 101 | E6: 10000 | I6: Adjusting Entries | O6: Closing Entries | T6: October 31,2017 | AB6: For the Month Ended September 30,2024 | AI6: Date | AJ6: Explanation | AK6: Ref… | AL6: Debit + | AM6: Credit - | AN6: Balance | AP6: Date | AQ6: Explanation | AR6: Ref… | AS6: Debit + | AT6: Credit - | AU6: Balance | AW6: Date | AX6: Explanation | AY6: Ref… | AZ6: Debit + | BA6: Credit - | BB6: Balance | BD6: Date | BE6: Explanation | BF6: Ref… | BG6: Debit + | BH6: Credit - | BI6: Balance | BK6: Date | BL6: Explanation | BM6: Ref… | BN6: Debit - | BO6: Credit + | BP6: Balance | BR6: Date | BS6: Explanation | BT6: Ref… | BU6: Debit - | BV6: Credit + | BW6: Balance | BY6: Date | BZ6: Explanation | CA6: Ref… | CB6: Debit - | CC6: Credit + | CD6: Balance | CF6: Date | CG6: Explanation | CH6: Ref… | CI6: Debit - | CJ6: Credit + | CK6: Balance | CM6: Date | CN6: Explanation | CO6: Ref… | CP6: Debit + | CQ6: Credit - | CR6: Balance | CT6: Date | CU6: Explanation | CV6: Ref… | CW6: Debit - | CX6: Credit + | CY6: Balance | DA6: Date | DB6: Explanation | DC6: Ref… | DD6: Debit + | DE6: Credit - | DF6: Balance
C7: Owner's Capital | D7: 301 | F7: 10000 | H7: Oct. 31 | I7: Supplies Expense | J7: 631 | K7: 1500 | N7: 2017 Oct. 31 | O7: Serivece Revenue | P7: 400 | Q7: 10600 | AI7: 2017 Oct. 1 | AK7: =F4 -> J1 | AL7: =E6 -> 10000 | AN7: =AL7 -> 10000 | AP7: 2017 Oct. 5 | AR7: J1 | AS7: =E26 -> 2500 | AU7: =AS7 -> 2500 | AW7: 2017 Oct. 4 | AY7: J1 | AZ7: =E22 -> 600 | BB7: =AZ7 -> 600 | BD7: 2017 Oct. 4 | BF7: J1 | BG7: =E10 -> 5000 | BI7: =BG7 -> 5000 | BK7: 2017 Oct. 1 | BM7: J1 | BO7: =F11 -> 5000 | BP7: =BO7 -> 5000 | BR7: 2017 Oct. 4 | BT7: J1 | BV7: =F27 -> 2500 | BW7: =BV7 -> 2500 | BY7: 2017 Oct. 4 | CA7: J1 | CC7: =F15 -> 1200 | CD7: =CC7 -> 1200 | CF7: 2017 Oct. 4 | CH7: J1 | CJ7: =F7 -> 10000 | CK7: =CJ7 -> 10000 | CM7: 2017 Oct. 4 | CO7: J1 | CP7: =E30 -> 500 | CR7: =CP7 -> 500 | CT7: 2017 Oct. 4 | CV7: J1 | CX7: =F39 -> 10000 | CY7: =CX7 -> 10000 | DA7: 2017 Oct. 4 | DC7: J1 | DD7: =E34 -> 4000 | DF7: =DD7 -> 4000
C8: (Owner's investment of cash in business) | I8: Supplies | J8: 126 | L8: 1500 | O8: Income Summary | P8: 350 | R8: 10600 | V8: Debit | X8: Credit | AC8: Revenues | AI8: 2 | AK8: =F4 -> J1 | AL8: =E14 -> 1200 | AN8: =AN7+AL8-AM8 -> 11200 | AP8: 2017 Oct. 31 | AQ8: Adj.entry | AR8: j2 | AT8: 1500 | AU8: =AU7+AS8-AT8 -> 1000 | AW8: 2017 Oct. 31 | AX8: Adj.entry | AY8: j2 | BA8: 50 | BB8: =BB7+AZ8-BA8 -> 550 | BI8: =BI7+BG8-BH8 -> 5000 | BP8: =BP7+BO8-BN8 -> 5000 | BW8: =BW7+BV8-BU8 -> 2500 | CD8: =CD7+CC8-CA8 -> 1200 | CK8: =CK7+CJ8-CI8 -> 10000 | CR8: =CR7+CP8-CQ8 -> 500 | CT8: 2017 Oct. 31 | CU8: Adj.entry | CV8: j2 | CX8: 400 | CY8: =CY7+CX8-CW8 -> 10400 | DF8: =DF7+DD8-DE8 -> 4000
I9: (To record supplies used) | O9: (To record supplies used) | U9: Cash | V9: =AN14 -> 15200 | AD9: Serive Revenue | AF9: =X22 -> -10600 | AI9: 3 | AK9: =F4 -> J1 | AM9: =F19 -> 900 | AN9: =AN8+AL9-AM9 -> 10300 | AS9: =SUM(AS7:AS8) -> 2500 | AT9: =SUM(AT7:AT8) -> 1500 | AU9: =AU8 -> 1000 | AZ9: =SUM(AZ7:AZ8) -> 600 | BA9: =SUM(BA7:BA8) -> 50 | BB9: =BB8 -> 550 | BG9: =SUM(BG7:BG8) -> 5000 | BH9: =SUM(BH7:BH8) -> 0 | BI9: =BI8 -> 5000 | BN9: =SUM(BN7:BN8) -> 0 | BO9: =SUM(BO7:BO8) -> 5000 | BP9: =BP8 -> 5000 | BU9: =SUM(BU7:BU8) -> 0 | BV9: =SUM(BV7:BV8) -> 2500 | BW9: =BW8 -> 2500 | CB9: =SUM(CB7:CB8) -> 0 | CC9: =SUM(CC7:CC8) -> 1200 | CD9: =CD8 -> 1200 | CI9: =SUM(CI7:CI8) -> 0 | CJ9: =SUM(CJ7:CJ8) -> 10000 | CK9: =CK8 -> 10000 | CP9: =SUM(CP7:CP8) -> 500 | CQ9: =SUM(CQ7:CQ8) -> 0 | CR9: =CR8 -> 500 | CT9: 2017 Oct. 31 | CU9: Adj.entry | CV9: j2 | CX9: 200 | CY9: =CY8+CX9-CW9 -> 10600 | DD9: =SUM(DD7:DD8) -> 4000 | DE9: =SUM(DE7:DE8) -> 0 | DF9: =DF8 -> 4000
B10: 1 | C10: Eqiument | D10: 157 | E10: 5000 | U10: Accounts Receivable | V10: =BB16 -> 200 | AC10: Expense | AI10: 4 | AK10: =F4 -> J1 | AM10: =F23 -> 600 | AN10: =AN9+AL10-AM10 -> 9700 | CT10: 2017 Oct. 31 | CU10: Closing Entries | CV10: j3 | CW10: =Q7 -> 10600 | CY10: =CY9+CX10-CW10 -> 0
C11: Notes payable | D11: 200 | F11: 5000 | H11: 31 | I11: Insurance Expense | J11: 722 | K11: 50 | N11: 31 | O11: Income Summary | P11: 350 | Q11: 7740 | U11: Supplies | V11: =AU9 -> 1000 | AD11: Salaries and Wages expense | AE11: =V23 -> 0 | AI11: 20 | AK11: =F4 -> J1 | AM11: =F31 -> 500 | AN11: =AN10+AL11-AM11 -> 9200 | AW11: Accounts Receivable | BR11: Interest Payable | CW11: =SUM(CW6:CW7) -> 0 | CX11: =SUM(CX6:CX7) -> 10000 | CY11: =CY10-CW10 -> -10600 | DA11: Rent Expense
C12: (Isued 3-month,, 12/ note for office) | I12: Prepaid Insurance | J12: 130 | L12: 50 | O12: Supplies Expense | P12: 631 | R12: 1500 | U12: Prepaid Insurance | V12: =BB9 -> 550 | AD12: Supplies Expense | AE12: =V24 -> 0 | AI12: 26 | AK12: =F4 -> J1 | AM12: =F35 -> 4000 | AN12: =AN11+AL12-AM12 -> 5200 | AW12: No. 112 | BR12: No. 230 | DA12: No. 729
I13: (To record insurance expired ) | O13: Depercation Expense | P13: 711 | R13: 40 | U13: Eqiument | V13: =BI9 -> 5000 | AD13: Rent Expense | AE13: =V25 -> 900 | AI13: 31 | AK13: =F4 -> J1 | AL13: =E38 -> 10000 | AN13: =AN12+AL13-AM13 -> 15200 | AW13: Date | AX13: Explanation | AY13: Ref… | AZ13: Debit + | BA13: Credit - | BB13: Balance | BR13: Date | BS13: Explanation | BT13: Ref… | BU13: Debit - | BV13: Credit + | BW13: Balance | CT13: Income Summary | DA13: Date | DB13: Explanation | DC13: Ref… | DD13: Debit + | DE13: Credit - | DF13: Balance
B14: 2 | C14: Cash | D14: 101 | E14: 1200 | O14: Insurance Expense | P14: 722 | R14: 50 | U14: Accumulateted Depercation---Eqiupment | X14: =AU23 -> 40 | AD14: Insurance Expense | AE14: =V26 -> 0 | AL14: =SUM(AL7:AL13) -> 21200 | AM14: =SUM(AM7:AM13) -> 6000 | AN14: =AN13 -> 15200 | AW14: 2017 Oct. 31 | AX14: Adj.entry | AY14: j2 | AZ14: 200 | BB14: =AZ14 -> 200 | BR14: 2017 Oct. 31 | BS14: Adj.entry | BT14: j2 | BV14: 50 | BW14: =BV14 -> 50 | CT14: No. 350 | DA14: 2017 Oct. 4 | DC14: J1 | DD14: =E18 -> 900 | DF14: =DD14 -> 900
C15: Unearned Serivice Revenue | D15: 209 | F15: 1200 | H15: 31 | I15: Depercation Expense | J15: 711 | K15: 40 | O15: Salaries and Wages Expense | P15: 726 | R15: 5200 | U15: Notes payable | X15: =BP9 -> 5000 | AD15: Interest Expense | AE15: =V27 -> 50 | BB15: =BB14+AZ15-BA15 -> 200 | BW15: =BW14+BV15-BU15 -> 50 | CT15: Date | CU15: Explanation | CV15: Ref… | CW15: Debit - | CX15: Credit + | CY15: Balance | DF15: =DF14+DD15-DE15 -> 900
C16: (Received cash from R. Knox for future service) | I16: Accumulateted--Depercation Expense | J16: 158 | L16: 40 | O16: Rent Expense | P16: 729 | R16: 900 | U16: Accounts Payable | X16: =BW9 -> 2500 | AD16: Depercation Expense | AE16: =V28 -> 0 | AZ16: =SUM(AZ14:AZ15) -> 200 | BA16: =SUM(BA14:BA15) -> 0 | BB16: =BB15 -> 200 | BU16: =SUM(BU14:BU15) -> 0 | BV16: =SUM(BV14:BV15) -> 50 | BW16: =BW15 -> 50 | CT16: 2017 Oct. 31 | CU16: Closing Entries | CV16: j3 | CW16: =Q13 -> 0 | CY16: =CY15+CX16-CW16 -> #VALUE! | DD16: =SUM(DD14:DD15) -> 900 | DE16: =SUM(DE14:DE15) -> 0 | DF16: =DF15 -> 900
I17: (To record monthly depreciation) | O17: Interest Expense | P17: 905 | R17: 50 | U17: Interest payable | X17: =BW16 -> 50 | AD17: Total Expense | AF17: =SUM(AE11:AE16) -> 950 | CT17: 2017 Oct. 31 | CU17: Closing Entries | CV17: j3 | CX17: =Q11 -> 7740 | CY17: =CY16+CX17-CW17 -> #VALUE!
B18: 3 | C18: Rent Expense | D18: 729 | E18: 900 | O18: (To close net income accounts) | U18: Unearned Serivice Revenue | X18: =DF45 -> 800 | AC18: Net income | AF18: =AF9-AF17 -> -11550 | AP18: Accumulateted--Depercation Eqiument | BR18: Salaries and Wages Payable | CT18: 2017 Oct. 31 | CU18: Closing Entries | CV18: j3 | CY18: =CY17+CX18-CW18 -> #VALUE! | DA18: Insurance Expense
C19: Cash | D19: 101 | F19: 900 | H19: 31 | I19: Unearned Serivice Revenue | J19: 209 | K19: 400 | U19: Salaries and Wages payable | X19: ='Adjusting the Accounts 3'!BQ23 -> 1200 | AP19: No. 158 | BR19: No. 212 | CY19: =CY18+CX19-CW19 -> #VALUE! | DA19: No. 722
C20: (Paid October rent) | I20: Service Revenue | J20: 400 | L20: 400 | N20: 31 | O20: Income Summary | P20: 350 | Q20: 2860 | U20: Owner's Capital | X20: =CY11 -> -10600 | AP20: Date | AQ20: Explanation | AR20: Ref… | AS20: Debit + | AT20: Credit - | AU20: Balance | BR20: Date | BS20: Explanation | BT20: Ref… | BU20: Debit + | BV20: Credit - | BW20: Balance | CW20: =SUM(CW15:CW16) -> 0 | CX20: =SUM(CX15:CX16) -> 0 | CY20: =CY19-CW19 -> #VALUE! | DA20: Date | DB20: Explanation | DC20: Ref… | DD20: Debit + | DE20: Credit - | DF20: Balance
I21: (To record interest on motes payable) | O21: Owner's Capital | P21: 301 | R21: 2860 | U21: Owner's Capital | V21: =CR9 -> 500 | AB21: Softbyte Inc. | AP21: 2017 Oct. 31 | AQ21: Adj.entry | AR21: j2 | AT21: 40 | AU21: =AT21 -> 40 | BR21: 2017 Oct. 31 | BS21: Adj.entry | BT21: j2 | BV21: 1200 | BW21: =BV21 -> 1200 | DA21: 2017 Oct. 31 | DB21: Adj.entry | DC21: j2 | DD21: 50 | DF21: =DD21 -> 50
B22: 4 | C22: Prepaid Insurance | D22: 130 | E22: 600 | O22: (To close net income to Capital) | U22: Service Revenue | X22: =CY11 -> -10600 | AB22: Retained Ernings Statement | AU22: =AU21+AS22-AT22 -> 40 | BW22: =BW21+BU22-BV22 -> 1200 | DE22: =R14 -> 50 | DF22: =DF21+DD22-DE22 -> 0
C23: Cash | D23: 101 | F23: 600 | H23: 31 | I23: Accounts Receivable | J23: 112 | K23: 200 | U23: Salaries and Wages Expense | V23: =DF31 -> 0 | AB23: For the Month Ended September 30,204 | AS23: =SUM(AS21:AS22) -> 0 | AT23: =SUM(AT21:AT22) -> 40 | AU23: =AU22 -> 40 | BU23: =SUM(BU21:BU22) -> 0 | BV23: =SUM(BV21:BV22) -> 1200 | BW23: =BW22 -> 1200 | DD23: =SUM(DD21:DD22) -> 50 | DE23: =SUM(DE21:DE22) -> 50 | DF23: =DF22+DD23-DE23 -> 0
C24: (Paid one-year policy; effective date October 1) | I24: Service Revenue | J24: 400 | L24: 200 | N24: 31 | O24: Owner's Capital | P24: 301 | Q24: 500 | U24: Supplies Expense | V24: =DF59 -> 0
I25: (To record revevue for services performed) | O25: Owner's Drawings | P25: 306 | R25: 500 | U25: Rent Expense | V25: =DF16 -> 900 | AD25: Retined earinihg, September 1 | AF25: 0 | DA25: Salaries and Wages Expense
B26: 5 | C26: Supplies | D26: 126 | E26: 2500 | O26: (To close Drawings to Capital) | U26: Insurance Expense | V26: =DF23 -> 0 | AD26: Add: Investments | AF26: 10000 | DA26: No. 726
C27: Accounts Payable | D27: 201 | F27: 2500 | H27: 31 | I27: Interest Expense | J27: 905 | K27: 50 | U27: Interest Expense | V27: =DF38 -> 50 | DA27: Date | DB27: Explanation | DC27: Ref… | DD27: Debit + | DE27: Credit - | DF27: Balance
C28: (Purchased supplies on account from Aero suply) | I28: Interest Payable | J28: 230 | L28: 50 | Q28: =SUM(Q7:Q27) -> 21700 | R28: =SUM(R7:R27) -> 21700 | U28: Depercation Expense | V28: =DF52 -> 0 | AD28: Net Income | AF28: =AF18 -> -11550 | DA28: 2017 Oct. 4 | DC28: J1 | DD28: 4000 | DF28: =DD28 -> 4000
I29: (To record interest on notes payable) | V29: =SUM(V9:V28) -> 23400 | X29: =SUM(X9:X29) -> 30190 | DA29: 2017 Oct. 31 | DB29: ` | DC29: j2 | DD29: 1200 | DF29: =DF28+DD29-DE29 -> 5200
B30: 20 | C30: Owner's Drawings | D30: 306 | E30: 500 | AD30: Owner's drawings | AF30: =V21 -> 500 | DE30: =R15 -> 5200 | DF30: =DF29-DE30 -> 0
C31: Cash | D31: 101 | F31: 500 | H31: 26 | I31: Salaries and Wages Expense | J31: 726 | K31: 1200 | AD31: Owner's capital October 31 | AF31: =AF26+AF28-AF30 -> -2050 | DD31: =SUM(DD28:DD29) -> 5200 | DE31: =SUM(DE28:DE29) -> 0 | DF31: =DF30 -> 0
C32: (Withdrew cash for personal use) | I32: Salaries and Wages Payable | J32: 212 | L32: 1200
I33: (To record accrued salaries and wages) | DA33: Interest Expense
B34: 26 | C34: Salaries and Wages Expense | D34: 726 | E34: 4000 | AB34: Softbyte Inc. | DA34: No. 905
C35: Cash | D35: 101 | F35: 4000 | K35: =SUM(K7:K34) -> 3440 | L35: =SUM(L7:L34) -> 3440 | AB35: Balance Sheet | DA35: Date | DB35: Explanation | DC35: Ref… | DD35: Debit + | DE35: Credit - | DF35: Balance
C36: (Paid salaries to date) | AB36: For the Month Ended September 30,204 | DA36: 2017 Oct. 31 | DB36: ` | DC36: j2 | DD36: 50 | DF36: =DD36 -> 50
AB37: Assets | DF37: =DF36+DD37-DE37 -> 50
B38: 31 | C38: Cash | D38: 101 | E38: 10000 | AC38: Cash | AF38: ='The Recording Process 2'!J9 -> 15200 | DD38: =SUM(DD36:DD37) -> 50 | DE38: =SUM(DE36:DE37) -> 0 | DF38: =DF37 -> 50
C39: Service Revenue | D39: 400 | F39: 10000 | AC39: Accounts Receivable | AF39: =V10 -> 200
C40: (Received cash for servics perforned) | AC40: Supplies | AF40: =V11 -> 1000 | DA40: Unearned Serivice Revenue
E41: =SUM(E6:E40) -> 34700 | F41: =SUM(F6:F40) -> 34700 | AC41: Prepaid Insurance | AF41: =V12 -> 550 | DA41: No. 209
AC42: Eqiument | AF42: =V13 -> 5000 | DA42: Date | DB42: Explanation | DC42: Ref… | DD42: Debit - | DE42: Credit + | DF42: Balance
...

Sheet Completing the Accounting Cycle
B2: Worksheets | Z2: GENERAL JOURNAL | AD2: J2 | AF2: Softbyte Inc. | AN2: Supplies
D3: Trial Balance | I3: Adjustments | N3: Adjusted Trial Balance | R3: Income Statement | V3: Balance Sheet | Z3: Date | AA3: Account Title | AB3: Ref… | AC3: Debit | AD3: Credit | AF3: Income Statement | AN3: No. 126
B4: Accounts Tiles | D4: Dr. | F4: Cr. | I4: Dr. | L4: Cr. | N4: Dr. | P4: Cr. | R4: Dr. | T4: Cr. | V4: Dr. | X4: Cr. | AA4: Closing Entries | AF4: For the Month Ended September 30,2024 | AN4: Date | AO4: Explanation | AP4: Ref… | AQ4: Debit + | AR4: Credit - | AS4: Balance
Z5: 2017 Oct. 31 | AA5: Serivece Revenue | AB5: 400 | AC5: 10600 | AN5: 2017 Oct. 5 | AP5: J1 | AQ5: 2500 | AS5: =AQ5 -> 2500
B6: Cash | D6: 15200 | N6: 15200 | V6: 15200 | AA6: Income Summary | AB6: 350 | AD6: 10600 | AG6: Revenues | AN6: 2017 Oct. 31 | AO6: Adj.entry | AP6: j2 | AR6: 1500 | AS6: =AS5+AQ6-AR6 -> 1000
B7: Supplies | D7: 2500 | K7: (a | L7: 1500 | N7: 1000 | V7: 1000 | AA7: (To record supplies used) | AH7: Serive Revenue | AK7: 10600
B8: Prepaid Insurance | D8: 600 | K8: (b | L8: 50 | N8: 550 | V8: 550 | AG8: Expense | AN8: Depercation Expense | AU8: Income Summary
B9: Eqiument | D9: 5000 | N9: 5000 | V9: 5000 | Z9: 31 | AA9: Income Summary | AB9: 350 | AC9: 7740 | AH9: Salaries and Wages expense | AI9: 5200 | AN9: No. 711 | AU9: No. 350
B10: Notes payable | F10: 5000 | P10: 5000 | X10: 5000 | AA10: Supplies Expense | AB10: 631 | AD10: 1500 | AH10: Supplies Expense | AI10: 1500 | AN10: Date | AO10: Explanation | AP10: Ref… | AQ10: Debit + | AR10: Credit - | AS10: Balance | AU10: Date | AV10: Explanation | AW10: Ref… | AX10: Debit + | AZ10: Credit - | BA10: Balance
B11: Accounts Payable | F11: 2500 | P11: 2500 | X11: 2500 | AA11: Depercation Expense | AB11: 711 | AD11: 40 | AH11: Rent Expense | AI11: 900 | AN11: 2017 Oct. 31 | AO11: Adj.entry | AP11: j2 | AQ11: 40 | AS11: =AQ11 -> 40 | AW11: 3 | AX11: 7740 | AY11: (I) | AZ11: 10600 | BA11: =AX11-AZ11 -> -2860
B12: Unearned Serivice Revenue | F12: 1200 | H12: (d | I12: 400 | P12: 800 | X12: 800 | AA12: Insurance Expense | AB12: 722 | AD12: 50 | AH12: Insurance Expense | AI12: 50 | AW12: 2 | AX12: 2860 | BA12: =AX12+AZ12 -> 2860
B13: Owner's Capital | F13: 10000 | P13: 10000 | X13: 10000 | AA13: Salaries and Wages Expense | AB13: 726 | AD13: 5200 | AH13: Interest Expense | AI13: 50 | AX13: =SUM(AX11:AX12) -> 10600 | AZ13: =SUM(AZ11:AZ12) -> 10600 | BA13: =SUM(BA11:BA12) -> 0
B14: Owner's Drawing | D14: 500 | N14: 500 | V14: 500 | AA14: Rent Expense | AB14: 729 | AD14: 900 | AH14: Depercation Expense | AI14: 40 | AN14: Insurance Expense
B15: Service Revenue | F15: 10000 | K15: (d | L15: 400 | T15: 10600 | AA15: Interest Expense | AB15: 905 | AD15: 50 | AN15: No. 722 | AU15: Owner's Capital
K16: (e | L16: 200 | AA16: (To close net income accounts) | AH16: Total Expense | AK16: =SUM(AI9:AI15) -> 7740 | AN16: Date | AO16: Explanation | AP16: Ref… | AQ16: Debit + | AR16: Credit - | AS16: Balance | AU16: No. 301
B17: Salaries and Wages Expense | D17: 4000 | H17: (g | I17: 1200 | N17: 5200 | R17: 5200 | AG17: Net income | AK17: =AK7-AK16 -> 2860 | AN17: 2017 Oct. 31 | AO17: Adj.entry | AP17: j2 | AQ17: 50 | AS17: =AQ17 -> 50 | AU17: Date | AV17: Explanation | AW17: Ref… | AX17: Debit + | AZ17: Credit - | BA17: Balance
B18: Rent Expense | D18: 900 | N18: 900 | R18: 900 | Z18: 31 | AA18: Income Summary | AB18: 350 | AC18: 2860 | AW18: 3 | AX18: 500 | AY18: -4 | AZ18: 10000 | BA18: =AX18+AZ18 -> 10500
B19: Total | D19: =SUM(D6:D18) -> 28700 | F19: =SUM(F6:F18) -> 28700 | AA19: Owner's Capital | AB19: 301 | AD19: 2860 | AZ19: 2860 | BA19: =BA18-AX19+AZ19 -> 13360
AA20: (To close net income to Capital) | AF20: Softbyte Inc. | AN20: Salaries and Wages Expense | AX20: =SUM(AX18:AX19) -> 500 | AZ20: =SUM(AZ18:AZ19) -> 12860 | BA20: =SUM(BA18:BA19) -> 23860
B21: Supplies Expense | H21: (a | I21: 1500 | N21: 1500 | R21: 1500 | AF21: Retained Ernings Statement | AN21: No. 212
B22: Insurance Expense | H22: (b | I22: 50 | N22: 50 | R22: 50 | Z22: 31 | AA22: Owner's Capital | AB22: 301 | AC22: 500 | AF22: For the Month Ended September 30,204 | AN22: Date | AO22: Explanation | AP22: Ref… | AQ22: Debit + | AR22: Credit - | AS22: Balance
B23: Accumulateted Depercation---Eqiupment | K23: (c | L23: 40 | P23: 40 | X23: 40 | AA23: Owner's Drawings | AB23: 306 | AD23: 500 | AN23: 2017 Oct. 31 | AO23: Adj.entry | AP23: j2 | AR23: 1200 | AS23: =AR23 -> 1200
B24: Depercation Expense | H24: (c | I24: 40 | N24: 40 | R24: 40 | AA24: (To close Drawings to Capital) | AG24: Retined earinihg, September 1 | AK24: 0
B25: Accounts Receivable | H25: (e | I25: 200 | N25: 200 | V25: 200 | AG25: Add: Investments | AI25: 10000
B26: Interest Expense | H26: (f | I26: 50 | N26: 50 | R26: 50 | AC26: =SUM(AC5:AC25) -> 21700 | AD26: =SUM(AD5:AD25) -> 21700 | AG26: Net Income | AI26: 2860 | AK26: =AI25+AI26 -> 12860 | AN26: Rent Expense
B27: Interest payable | K27: (f | L27: 50 | P27: 50 | X27: 50 | AK27: =AK26 -> 12860 | AN27: No. 729
B28: Salaries and Wages payable | K28: (g | L28: 1200 | P28: 1200 | X28: 1200 | AG28: Less:Drawings | AK28: 500 | AN28: Date | AO28: Explanation | AP28: Ref… | AQ28: Debit + | AR28: Credit - | AS28: Balance
B29: Total | I29: =SUM(I5:I28) -> 3440 | L29: =SUM(L5:L28) -> 3440 | N29: =SUM(N5:N28) -> 30190 | P29: =SUM(P5:P28) -> 19590 | R29: =SUM(R5:R28) -> 7740 | T29: =SUM(T5:T28) -> 10600 | V29: =SUM(V5:V28) -> 22450 | X29: =SUM(X5:X28) -> 19590 | AG29: Owner's capital October 31 | AK29: 12360 | AN29: 2017 Oct. 4 | AP29: J1 | AQ29: 4000 | AS29: =AQ29 -> 4000
R31: =T29-R29 -> 2860 | X31: =V29-X29 -> 2860
R32: =R29+R31 -> 10600 | T32: =T29 -> 10600 | V32: =V29 -> 22450 | X32: =X29+X31 -> 22450 | AF32: Softbyte Inc. | AN32: Interest Expense
AF33: Balance Sheet | AN33: No. 905
AF34: For the Month Ended September 30,204 | AN34: Date | AO34: Explanation | AP34: Ref… | AQ34: Debit + | AR34: Credit - | AS34: Balance
AF35: Assets | AN35: 2017 Oct. 4 | AP35: J1 | AQ35: 50 | AS35: =AQ35 -> 50
AF36: Cash | AK36: 15200
AF37: Accounts Receivable | AK37: 200
AF38: Supplies | AK38: 1000
AF39: Prepaid Insurance | AK39: 550
AF40: Eqiument | AI40: 5000 | AJ40: 5000
AF41: Accumulateted--Depercation Expense | AI41: 40 | AJ41: 40 | AK41: 4960
AF42: Total Assets | AK42: =SUM(AK36:AK41) -> 21910
...
